Workbook
Name PRINT_TITLES_MI: 'ISS10102'!$4:$9

Sheet Bi-monthly net issuance
A2: Auction no. | B2: Date | C2: Issues (billions of UgShs.) a/ | D2: Paper | E2: Paper | F2: Maturities (billions of UgShs.) b/ | G2: Net Issuance
B3: 37776 | E3: 273 | F3: 7000000000
E4: 182 | F4: 6000000000
E5: 91 | F5: 4000000000
F7: =SUM(F3:F6) -> 17000000000
A9: 561 | B9: 37783 | C9: 10000000000 | D9: 91 | E9: 364 | F9: 13000000000
A10: , | C10: 12000000000 | D10: 182 | E10: 273 | F10: 7999800000
C11: 18000000000 | D11: 273 | E11: 182 | F11: 5999800000
C12: 25000000000 | D12: 364
C13: =SUM(C9:C12) -> 65000000000 | F13: =SUM(F9:F12) -> 26999600000
G14: =+C13-F13-F7 -> 21000400000
B15: =+B9+7 -> 37790 | E15: 364 | F15: 13000000000
E16: 273 | F16: 9000000000
E17: 182 | F17: 6000000000
E18: 91 | F18: 12000000000
F20: =SUM(F15:F19) -> 40000000000
A22: 562 | B22: 37797 | C22: 8000000000 | D22: 91 | E22: 364 | F22: 11999900000
C23: 13999900000 | D23: 182 | E23: 273 | F23: 10000000000
C24: 21000000000 | D24: 273 | E24: 182 | F24: 2969000000
C25: 28999900000 | D25: 364
C26: =SUM(C22:C25) -> 71999800000 | F26: =SUM(F22:F25) -> 24968900000
G27: =+C26-F26-F20 -> 7030900000
B28: 37804 | E28: 364 | F28: 12000000000
E29: 273 | F29: 8999900000
E30: 182 | F30: 2635700000
E31: 91 | F31: 5000000000
F33: =SUM(F28:F32) -> 28635600000
A35: 563 | B35: 37811 | C35: 10000000000 | D35: 91 | E35: 364 | F35: 10000000000
C36: 14999900000 | D36: 182 | E36: 182 | F36: 4000000000
C37: 25000000000 | D37: 273 | E37: 273 | F37: 8000000000
C38: 30000000000 | D38: 364
C39: =SUM(C35:C38) -> 79999900000 | F39: =SUM(F35:F38) -> 22000000000
G40: =+C39-F39-F33 -> 29364300000
B41: 37818 | E41: 364 | F41: 14000000000
E42: 273 | F42: 8000000000
E43: 182 | F43: 3500000000
E44: 91 | F44: 6291200000
F46: =SUM(F41:F45) -> 31791200000
A48: 564 | B48: 37825 | C48: 7000000000 | D48: 91 | E48: 364 | F48: 14000000000
C49: 12999800000 | D49: 182 | E49: 273 | F49: 10000000000
...

Sheet ISS10102
A2: Ref:ISS0001. WK3
A3: worksheet a
A4: - | B4: - | D4: - | E4: - | F4: - | G4: - | H4: - | I4: - | J4: - | K4: - | L4: - | M4: - | N4: - | O4: - | P4: - | Q4: -
A5: Auction | B5: Issue date | D5: Amount offered | E5: Total bids | F5: Over/(Under) | G5: Face Value of | H5: Cost Value | I5: Interest due | J5: Date due | K5: Duration | L5: Implicit annual | M5: Clearing | N5: Lowest | O5: Weighted | P5: Average | Q5: Annualised
A6: No | D6: in | E6: (Competitive & | F6: Subscribed | G6: issues | L6: interest rate | M6: factor | N6: factor | O6: Average | P6: Discount | Q6: yield
D7: Auction | E7: Uncompetitive) | M7: (%) | N7: (%) | O7: Price | P7: factor
B8: (1) | D8: (1a) | E8: (1b) | G8: (2) | H8: (3) | I8: (4) | J8: (5) | K8: (6) | L8: (9) | M8: (10) | N8: (11) | O8: (12) | P8: (13)
A9: - | B9: - | D9: - | E9: - | F9: - | G9: - | H9: - | I9: - | J9: - | K9: - | L9: - | M9: - | N9: - | O9: - | P9: - | Q9: -
A11: 469 | B11: 37076 | D11: 1500000000 | E11: 2402100000 | F11: =E11-D11 -> 902100000 | G11: 1500000000 | H11: 1473850685 | I11: =G11-H11 -> 26149315 | J11: =B11+K11 -> 37167 | K11: 91 | N11: 4.412 | O11: =H11/G11*100 -> 98.256712 | P11: =(100-O11)/100*(365/91)*100 -> 6.9923077 | Q11: =((100-O11)/O11*(365/91))*100 -> 7.1163664
D12: 1500000000 | E12: 2670000000 | F12: =E12-D12 -> 1170000000 | G12: 1500000000 | H12: 1440153500 | I12: =G12-H12 -> 59846500 | J12: =B11+K12+1 -> 37259 | K12: 182 | N12: 7.621 | O12: =H12/G12*100 -> 96.010233 | P12: =(100-O12)/100*(365/182)*100 -> 8.0014551 | Q12: =((100-O12)/O12*(365/182))*100 -> 8.3339607
D13: 4000000000 | E13: 5477000000 | F13: =E13-D13 -> 1477000000 | G13: 4000000000 | H13: 3698699840 | I13: =G13-H13 -> 301300160 | J13: =B11+K13+1 -> 37350 | K13: 273 | N13: 9.426 | O13: =H13/G13*100 -> 92.467496 | P13: =(100-O13)/100*(365/273)*100 -> 10.07093 | Q13: =((100-O13)/O13*(365/273))*100 -> 10.891319
D14: 5000000000 | E14: 6412000000 | F14: =E14-D14 -> 1412000000 | G14: 5000000000 | H14: 4459772680 | I14: =G14-H14 -> 540227320 | J14: =B11+K14+1 -> 37441 | K14: 364 | N14: 10.123 | O14: =H14/G14*100 -> 89.195454 | P14: =(100-O14)/100*(365/364)*100 -> 10.834229 | Q14: =((100-O14)/O14*(365/364))*100 -> 12.146616
A16: =A11+1 -> 470 | B16: =B11+7 -> 37083 | D16: 2000000000 | E16: 6763900000 | F16: =E16-D16 -> 4763900000 | G16: 2000000000 | H16: 1966357750 | I16: =G16-H16 -> 33642250 | J16: =B16+K16 -> 37174 | K16: 91 | N16: 6 | O16: =H16/G16*100 -> 98.317887 | P16: =(100-O16)/100*(365/91)*100 -> 6.7469348 | Q16: =((100-O16)/O16*(365/91))*100 -> 6.8623675
D17: 2000000000 | E17: 2030000000 | F17: =E17-D17 -> 30000000 | G17: 2000000000 | H17: 1895843600 | I17: =G17-H17 -> 104156400 | J17: =B16+K17+1 -> 37266 | K17: 182 | N17: 7.85 | O17: =H17/G17*100 -> 94.79218 | P17: =(100-O17)/100*(365/182)*100 -> 10.444254 | Q17: =((100-O17)/O17*(365/182))*100 -> 11.018055
D18: 5000000000 | E18: 5000000000 | F18: =E18-D18 -> 0 | G18: 5000000000 | H18: 4570702500 | I18: =G18-H18 -> 429297500 | J18: =B16+K18+1 -> 37357 | K18: 273 | N18: 10.629 | O18: =H18/G18*100 -> 91.41405 | P18: =(100-O18)/100*(365/273)*100 -> 11.479384 | Q18: =((100-O18)/O18*(365/273))*100 -> 12.55757
D19: 7000000000 | E19: 7000000000 | F19: =E19-D19 -> 0 | G19: 7000000000 | H19: 6220102016 | I19: =G19-H19 -> 779897984 | J19: =B16+K19+1 -> 37448 | K19: 364 | N19: 9.916 | O19: =H19/G19*100 -> 88.8586 | P19: =(100-O19)/100*(365/364)*100 -> 11.172008 | Q19: =((100-O19)/O19*(365/364))*100 -> 12.572793
A21: =A16+1 -> 471 | B21: =B16+7 -> 37090 | D21: 2000000000 | E21: 3562000000 | F21: =E21-D21 -> 1562000000 | G21: 2000000000 | H21: 1964154360 | I21: =G21-H21 -> 35845640 | J21: =B21+K21 -> 37181 | K21: 91 | N21: 6.746 | O21: =H21/G21*100 -> 98.207718 | P21: =(100-O21)/100*(365/91)*100 -> 7.1888234 | Q21: =((100-O21)/O21*(365/91))*100 -> 7.3200188
D22: 2000000000 | E22: 3088900000 | F22: =E22-D22 -> 1088900000 | G22: 2000000000 | H22: 1878252919 | I22: =G22-H22 -> 121747081 | J22: =B21+K22+1 -> 37273 | K22: 182 | N22: 11.03 | O22: =H22/G22*100 -> 93.912646 | P22: =(100-O22)/100*(365/182)*100 -> 12.208155 | Q22: =((100-O22)/O22*(365/182))*100 -> 12.999479
D23: 5000000000 | E23: 5000000000 | F23: =E23-D23 -> 0 | G23: 5000000000 | H23: 4483755000 | I23: =G23-H23 -> 516245000 | J23: =B21+K23+1 -> 37364 | K23: 273 | N23: 11.848 | O23: =H23/G23*100 -> 89.6751 | P23: =(100-O23)/100*(365/273)*100 -> 13.804353 | Q23: =((100-O23)/O23*(365/273))*100 -> 15.393742
D24: 7000000000 | E24: 7000000000 | F24: =E24-D24 -> 0 | G24: 7000000000 | H24: 6001002268 | I24: =G24-H24 -> 998997732 | J24: =B21+K24+1 -> 37455 | K24: 364 | N24: 11 | O24: =H24/G24*100 -> 85.728604 | P24: =(100-O24)/100*(365/364)*100 -> 14.310603 | Q24: =((100-O24)/O24*(365/364))*100 -> 16.692915
A26: =A21+1 -> 472 | B26: =B21+7 -> 37097 | D26: 3000000000 | E26: 3034500000 | F26: =E26-D26 -> 34500000 | G26: 3000000000 | H26: 2920291115 | I26: =G26-H26 -> 79708885 | J26: =B26+K26 -> 37188 | K26: 91 | N26: 7.019 | O26: =H26/G26*100 -> 97.343037 | P26: =(100-O26)/100*(365/91)*100 -> 10.657049 | Q26: =((100-O26)/O26*(365/91))*100 -> 10.947931
D27: 4000000000 | E27: 4000000000 | F27: =E27-D27 -> 0 | G27: 4000000000 | H27: 3676427332 | I27: =G27-H27 -> 323572668 | J27: =B26+K27+1 -> 37280 | K27: 182 | N27: 9.999 | O27: =H27/G27*100 -> 91.910683 | P27: =(100-O27)/100*(365/182)*100 -> 16.22308 | Q27: =((100-O27)/O27*(365/182))*100 -> 17.650919
D28: 5000000000 | E28: 5000000000 | F28: =E28-D28 -> 0 | G28: 5000000000 | H28: 4265972900 | I28: =G28-H28 -> 734027100 | J28: =B26+K28+1 -> 37371 | K28: 273 | N28: 12 | O28: =H28/G28*100 -> 85.319458 | P28: =(100-O28)/100*(365/273)*100 -> 19.627831 | Q28: =((100-O28)/O28*(365/273))*100 -> 23.005105
D29: 7000000000 | E29: 7000000000 | F29: =E29-D29 -> 0 | G29: 7000000000 | H29: 5421688900 | I29: =G29-H29 -> 1578311100 | J29: =B26+K29+1 -> 37462 | K29: 364 | N29: 16.713 | O29: =H29/G29*100 -> 77.452699 | P29: =(100-O29)/100*(365/364)*100 -> 22.609245 | Q29: =((100-O29)/O29*(365/364))*100 -> 29.191035
B31: TOTAL JULY 2001 | D31: =SUM(D11:D29) -> 63000000000 | E31: =SUM(E11:E29) -> 75440400000 | F31: =SUM(F11:F29) -> 12440400000 | G31: =SUM(G11:G29) -> 63000000000 | H31: =SUM(H11:H29) -> 56337027365 | I31: =SUM(I11:I29) -> 6662972635 | L31: Monthly Average of 91 day bill rate | O31: =AVERAGEA(O11,O16,O21,O26) -> 98.031339 | P31: =AVERAGEA(P11,P16,P21,P26) -> 7.8962786
L32: Monthly Average of 182 day bill rate | O32: =AVERAGEA(O12,O17,O22,O27) -> 94.156436 | P32: =AVERAGEA(P12,P17,P22,P27) -> 11.719236
L33: Monthly Average of 273 day bill rate | O33: =AVERAGEA(O13,O18,O23,O28) -> 89.719026 | P33: =AVERAGEA(P13,P18,P23,P28) -> 13.745625
L34: Monthly Average of 364 day bill rate | O34: =AVERAGEA(O14,O19,O24,O29) -> 85.308839 | P34: =AVERAGEA(P14,P19,P24,P29) -> 14.731521
A36: =A26+1 -> 473 | B36: =B26+7 -> 37104 | D36: 3000000000 | E36: 3000000000 | F36: =E36-D36 -> 0 | G36: 3000000000 | H36: 2899532650 | I36: =G36-H36 -> 100467350 | J36: =B36+K36 -> 37195 | K36: 91 | N36: 9.001 | O36: =H36/G36*100 -> 96.651088 | P36: =(100-O36)/100*(365/91)*100 -> 13.432448 | Q36: =((100-O36)/O36*(365/91))*100 -> 13.897875
D37: 4000000000 | E37: 8279400000 | F37: =E37-D37 -> 4279400000 | G37: 4000000000 | H37: 3670506802 | I37: =G37-H37 -> 329493198 | J37: =B36+K37+1 -> 37287 | K37: 182 | N37: 13.116 | O37: =H37/G37*100 -> 91.76267 | P37: =(100-O37)/100*(365/182)*100 -> 16.51992 | Q37: =((100-O37)/O37*(365/182))*100 -> 18.002876
D38: 4000000000 | E38: 10723700000 | F38: =E38-D38 -> 6723700000 | G38: 3999900000 | H38: 3411615570 | I38: =G38-H38 -> 588284430 | J38: =B36+K38+1 -> 37378 | K38: 273 | N38: 17.381 | O38: =H38/G38*100 -> 85.292522 | P38: =(100-O38)/100*(365/273)*100 -> 19.663845 | Q38: =((100-O38)/O38*(365/273))*100 -> 23.054594
D39: 5000000000 | E39: 15353400000 | F39: =E39-D39 -> 10353400000 | G39: 5000000000 | H39: 4012973427 | I39: =G39-H39 -> 987026573 | J39: =B36+K39+1 -> 37469 | K39: 364 | N39: 15.041 | O39: =H39/G39*100 -> 80.259469 | P39: =(100-O39)/100*(365/364)*100 -> 19.794764 | Q39: =((100-O39)/O39*(365/364))*100 -> 24.663462
A41: =A36+1 -> 474 | B41: =B36+7 -> 37111 | D41: 3000000000 | E41: 4969200000 | F41: =E41-D41 -> 1969200000 | G41: 3000000000 | H41: 2895219779 | I41: =G41-H41 -> 104780221 | J41: =B41+K41 -> 37202 | K41: 91 | N41: 12.001 | O41: =H41/G41*100 -> 96.507326 | P41: =(100-O41)/100*(365/91)*100 -> 14.009077 | Q41: =((100-O41)/O41*(365/91))*100 -> 14.516076
D42: 4000000000 | E42: 6417600000 | F42: =E42-D42 -> 2417600000 | G42: 4000000000 | H42: 3670675212 | I42: =G42-H42 -> 329324788 | J42: =B41+K42+1 -> 37294 | K42: 182 | N42: 14.038 | O42: =H42/G42*100 -> 91.76688 | P42: =(100-O42)/100*(365/182)*100 -> 16.511476 | Q42: =((100-O42)/O42*(365/182))*100 -> 17.992849
D43: 6000000000 | E43: 10552200000 | F43: =E43-D43 -> 4552200000 | G43: 6000000000 | H43: 5070862258 | I43: =G43-H43 -> 929137742 | J43: =B41+K43+1 -> 37385 | K43: 273 | N43: 18 | O43: =H43/G43*100 -> 84.514371 | P43: =(100-O43)/100*(365/273)*100 -> 20.704229 | Q43: =((100-O43)/O43*(365/273))*100 -> 24.49788
D44: 7000000000 | E44: 15452500000 | F44: =E44-D44 -> 8452500000 | G44: 7000000000 | H44: 5594245390 | I44: =G44-H44 -> 1405754610 | J44: =B41+K44+1 -> 37476 | K44: 364 | N44: 18 | O44: =H44/G44*100 -> 79.917791 | P44: =(100-O44)/100*(365/364)*100 -> 20.13738 | Q44: =((100-O44)/O44*(365/364))*100 -> 25.197618
A46: =A41+1 -> 475 | B46: =B41+7 -> 37118 | D46: 3000000000 | E46: 8552600000 | F46: =E46-D46 -> 5552600000 | G46: 3000000000 | H46: 2897370000 | I46: =G46-H46 -> 102630000 | J46: =B46+K46 -> 37209 | K46: 91 | N46: 10.998 | O46: =H46/G46*100 -> 96.579 | P46: =(100-O46)/100*(365/91)*100 -> 13.721593 | Q46: =((100-O46)/O46*(365/91))*100 -> 14.207637
D47: 4000000000 | E47: 9595200000 | F47: =E47-D47 -> 5595200000 | G47: 4000000000 | H47: 3683572728 | I47: =G47-H47 -> 316427272 | J47: =B46+K47+1 -> 37301 | K47: 182 | N47: 15.673 | O47: =H47/G47*100 -> 92.089318 | P47: =(100-O47)/100*(365/182)*100 -> 15.864829 | Q47: =((100-O47)/O47*(365/182))*100 -> 17.227654
D48: 5000000000 | E48: 9401000000 | F48: =E48-D48 -> 4401000000 | G48: 5000000000 | H48: 4213782060 | I48: =G48-H48 -> 786217940 | J48: =B46+K48+1 -> 37392 | K48: 273 | N48: 18.918 | O48: =H48/G48*100 -> 84.275641 | P48: =(100-O48)/100*(365/273)*100 -> 21.02341 | Q48: =((100-O48)/O48*(365/273))*100 -> 24.94601
D49: 8000000000 | E49: 11284200000 | F49: =E49-D49 -> 3284200000 | G49: 8000000000 | H49: 6279888734 | I49: =G49-H49 -> 1720111266 | J49: =B46+K49+1 -> 37483 | K49: 364 | N49: 17.047 | O49: =H49/G49*100 -> 78.498609 | P49: =(100-O49)/100*(365/364)*100 -> 21.560461 | Q49: =((100-O49)/O49*(365/364))*100 -> 27.466042
...

Sheet maturities - 91
A2: Ref:ISS0001. WK3
A3: worksheet a
A4: - | B4: - | C4: - | D4: - | E4: - | F4: - | G4: - | H4: - | I4: - | J4: - | K4: - | L4: - | M4: - | N4: - | O4: - | Q4: -
A5: Auction | B5: Issue date | C5: Amount offered | D5: Total bids | E5: Over/(Under) | F5: Face Value of | G5: Cost Value | H5: Interest due | I5: Date due | J5: Duration | K5: Implicit annual | L5: Clearing | M5: Lowest | N5: Weighted | O5: Average | P5: Money Market yield | Q5: Annualised | R5: Bid to cover ratios
A6: No | C6: in | D6: (Competitive & | E6: Subscribed | F6: issues | K6: interest rate | L6: factor | M6: factor | N6: Average | O6: Discount | Q6: yield
C7: Auction | D7: Uncompetitive) | L7: (%) | M7: (%) | N7: Price | O7: factor
B8: (1) | C8: (1a) | D8: (1b) | F8: (2) | G8: (3) | H8: (4) | I8: (5) | J8: (6) | K8: (9) | L8: (10) | M8: (11) | N8: (12) | O8: (13)
A9: - | B9: - | D9: - | E9: - | F9: - | G9: - | H9: - | I9: - | J9: - | K9: - | L9: - | M9: - | N9: - | O9: - | Q9: -
A11: ='ISS10102'!A11 -> 469 | B11: ='ISS10102'!B11 -> 37076 | C11: ='ISS10102'!D11 -> 1500000000 | D11: ='ISS10102'!E11 -> 2402100000 | E11: ='ISS10102'!F11 -> 902100000 | F11: ='ISS10102'!G11 -> 1500000000 | G11: ='ISS10102'!H11 -> 1473850685 | H11: ='ISS10102'!I11 -> 26149315 | I11: ='ISS10102'!J11 -> 37167 | J11: ='ISS10102'!K11 -> 91 | ... O11: ='ISS10102'!P11 -> 6.9923077 | Q11: ='ISS10102'!Q11 -> 7.1163664 | R11: =D11/C11 -> 1.6014
A12: ='ISS10102'!A16 -> 470 | B12: ='ISS10102'!B16 -> 37083 | C12: ='ISS10102'!D16 -> 2000000000 | D12: ='ISS10102'!E16 -> 6763900000 | E12: ='ISS10102'!F16 -> 4763900000 | F12: ='ISS10102'!G16 -> 2000000000 | G12: ='ISS10102'!H16 -> 1966357750 | H12: ='ISS10102'!I16 -> 33642250 | I12: ='ISS10102'!J16 -> 37174 | J12: ='ISS10102'!K16 -> 91 | ... O12: ='ISS10102'!P16 -> 6.7469348 | Q12: ='ISS10102'!Q16 -> 6.8623675 | R12: =+D12/F12 -> 3.38195 | T12: 2001 | U12: =+SUMIF(#REF!,T12,G:G) -> #REF!
A13: ='ISS10102'!A21 -> 471 | B13: ='ISS10102'!B21 -> 37090 | C13: ='ISS10102'!D21 -> 2000000000 | D13: ='ISS10102'!E21 -> 3562000000 | E13: ='ISS10102'!F21 -> 1562000000 | F13: ='ISS10102'!G21 -> 2000000000 | G13: ='ISS10102'!H21 -> 1964154360 | H13: ='ISS10102'!I21 -> 35845640 | I13: ='ISS10102'!J21 -> 37181 | J13: ='ISS10102'!K21 -> 91 | ... O13: ='ISS10102'!P21 -> 7.1888234 | Q13: ='ISS10102'!Q21 -> 7.3200188 | R13: =+D13/F13 -> 1.781 | T13: 2002 | U13: =+SUMIF(#REF!,T13,G:G) -> #REF!
A14: ='ISS10102'!A26 -> 472 | B14: ='ISS10102'!B26 -> 37097 | C14: ='ISS10102'!D26 -> 3000000000 | D14: ='ISS10102'!E26 -> 3034500000 | E14: ='ISS10102'!F26 -> 34500000 | F14: ='ISS10102'!G26 -> 3000000000 | G14: ='ISS10102'!H26 -> 2920291115 | H14: ='ISS10102'!I26 -> 79708885 | I14: ='ISS10102'!J26 -> 37188 | J14: ='ISS10102'!K26 -> 91 | ... O14: ='ISS10102'!P26 -> 10.657049 | Q14: ='ISS10102'!Q26 -> 10.947931 | R14: =+D14/F14 -> 1.0115 | T14: 2003 | U14: =+SUMIF(#REF!,T14,G:G) -> #REF!
A15: ='ISS10102'!A36 -> 473 | B15: ='ISS10102'!B36 -> 37104 | C15: ='ISS10102'!D36 -> 3000000000 | D15: ='ISS10102'!E36 -> 3000000000 | E15: ='ISS10102'!F36 -> 0 | F15: ='ISS10102'!G36 -> 3000000000 | G15: ='ISS10102'!H36 -> 2899532650 | H15: ='ISS10102'!I36 -> 100467350 | I15: ='ISS10102'!J36 -> 37195 | J15: ='ISS10102'!K36 -> 91 | ... O15: ='ISS10102'!P36 -> 13.432448 | Q15: ='ISS10102'!Q36 -> 13.897875 | R15: =+D15/F15 -> 1 | T15: 2004 | U15: =+SUMIF(#REF!,T15,G:G) -> #REF!
F16: =SUM(F11:F15) -> 11500000000 | R16: =+D16/F16 -> 0 | T16: 2005 | U16: =+SUMIF(#REF!,T16,G:G) -> #REF!
A17: ='ISS10102'!A41 -> 474 | B17: ='ISS10102'!B41 -> 37111 | C17: ='ISS10102'!D41 -> 3000000000 | D17: ='ISS10102'!E41 -> 4969200000 | E17: ='ISS10102'!F41 -> 1969200000 | F17: ='ISS10102'!G41 -> 3000000000 | G17: ='ISS10102'!H41 -> 2895219779 | H17: ='ISS10102'!I41 -> 104780221 | I17: ='ISS10102'!J41 -> 37202 | J17: ='ISS10102'!K41 -> 91 | ... O17: ='ISS10102'!P41 -> 14.009077 | Q17: ='ISS10102'!Q41 -> 14.516076 | R17: =+D17/F17 -> 1.6564 | T17: 2006 | U17: =+SUMIF(#REF!,T17,G:G) -> #REF!
A18: ='ISS10102'!A46 -> 475 | B18: ='ISS10102'!B46 -> 37118 | C18: ='ISS10102'!D46 -> 3000000000 | D18: ='ISS10102'!E46 -> 8552600000 | E18: ='ISS10102'!F46 -> 5552600000 | F18: ='ISS10102'!G46 -> 3000000000 | G18: ='ISS10102'!H46 -> 2897370000 | H18: ='ISS10102'!I46 -> 102630000 | I18: ='ISS10102'!J46 -> 37209 | J18: ='ISS10102'!K46 -> 91 | ... O18: ='ISS10102'!P46 -> 13.721593 | Q18: ='ISS10102'!Q46 -> 14.207637 | R18: =+D18/F18 -> 2.8508667 | T18: 2007 | U18: =+SUMIF(#REF!,T18,G:G) -> #REF!
A19: ='ISS10102'!A51 -> 476 | B19: ='ISS10102'!B51 -> 37125 | C19: ='ISS10102'!D51 -> 3000000000 | D19: ='ISS10102'!E51 -> 6090200000 | E19: ='ISS10102'!F51 -> 3090200000 | F19: ='ISS10102'!G51 -> 3000000000 | G19: ='ISS10102'!H51 -> 2897927590 | H19: ='ISS10102'!I51 -> 102072410 | I19: ='ISS10102'!J51 -> 37216 | J19: ='ISS10102'!K51 -> 91 | ... O19: ='ISS10102'!P51 -> 13.647044 | Q19: ='ISS10102'!Q51 -> 14.127728 | R19: =+D19/F19 -> 2.0300667 | T19: 2008 | U19: =+SUMIF(#REF!,T19,G:G) -> #REF!
A20: ='ISS10102'!A56 -> 477 | B20: ='ISS10102'!B56 -> 37132 | C20: ='ISS10102'!D56 -> 2000000000 | D20: ='ISS10102'!E56 -> 4022300000 | E20: ='ISS10102'!F56 -> 2022300000 | F20: ='ISS10102'!G56 -> 2000000000 | G20: ='ISS10102'!H56 -> 1933101900 | H20: ='ISS10102'!I56 -> 66898100 | I20: ='ISS10102'!J56 -> 37223 | J20: ='ISS10102'!K56 -> 91 | ... O20: ='ISS10102'!P56 -> 13.416377 | Q20: ='ISS10102'!Q56 -> 13.880673 | R20: =+D20/F20 -> 2.01115 | T20: 2009 | U20: =+SUMIF(#REF!,T20,G:G) -> #REF!
F21: =SUM(F17:F20) -> 11000000000 | R21: =+D21/F21 -> 0 | T21: 2010 | U21: =+SUMIF(#REF!,T21,G:G) -> #REF!
A22: ='ISS10102'!A66 -> 478 | B22: ='ISS10102'!B66 -> 37139 | C22: ='ISS10102'!D66 -> 3000000000 | D22: ='ISS10102'!E66 -> 3000000000 | E22: ='ISS10102'!F66 -> 0 | F22: ='ISS10102'!G66 -> 3000000000 | G22: ='ISS10102'!H66 -> 2902667373 | H22: ='ISS10102'!I66 -> 97332627 | I22: ='ISS10102'!J66 -> 37230 | J22: ='ISS10102'!K66 -> 91 | ... O22: ='ISS10102'!P66 -> 13.013337 | Q22: ='ISS10102'!Q66 -> 13.449702 | R22: =+D22/F22 -> 1 | T22: 2011 | U22: =+SUMIF(#REF!,T22,G:G) -> #REF!
A23: ='ISS10102'!A71 -> 479 | B23: ='ISS10102'!B71 -> 37146 | C23: ='ISS10102'!D71 -> 3000000000 | D23: ='ISS10102'!E71 -> 7713300000 | E23: ='ISS10102'!F71 -> 4713300000 | F23: ='ISS10102'!G71 -> 2999900000 | G23: ='ISS10102'!H71 -> 2910595503 | H23: ='ISS10102'!I71 -> 89304497 | I23: ='ISS10102'!J71 -> 37237 | J23: ='ISS10102'!K71 -> 91 | ... O23: ='ISS10102'!P71 -> 11.940377 | Q23: ='ISS10102'!Q71 -> 12.306738 | R23: =+D23/F23 -> 2.5711857 | T23: 2012 | U23: =+SUMIF(#REF!,T23,G:G) -> #REF!
A24: ='ISS10102'!A76 -> 480 | B24: ='ISS10102'!B76 -> 37153 | C24: ='ISS10102'!D76 -> 3000000000 | D24: ='ISS10102'!E76 -> 6345200000 | E24: ='ISS10102'!F76 -> 3345200000 | F24: ='ISS10102'!G76 -> 3000000000 | G24: ='ISS10102'!H76 -> 2914052620 | H24: ='ISS10102'!I76 -> 85947380 | I24: ='ISS10102'!J76 -> 37244 | J24: ='ISS10102'!K76 -> 91 | ... O24: ='ISS10102'!P76 -> 11.491133 | Q24: ='ISS10102'!Q76 -> 11.830054 | R24: =+D24/F24 -> 2.1150667 | T24: 2013 | U24: =+SUMIF(#REF!,T24,G:G) -> #REF!
A25: ='ISS10102'!A81 -> 481 | B25: ='ISS10102'!B81 -> 37160 | C25: ='ISS10102'!D81 -> 2000000000 | D25: ='ISS10102'!E81 -> 3299500000 | E25: ='ISS10102'!F81 -> 1299500000 | F25: ='ISS10102'!G81 -> 2000000000 | G25: ='ISS10102'!H81 -> 1941382978 | H25: ='ISS10102'!I81 -> 58617022 | I25: ='ISS10102'!J81 -> 37251 | J25: ='ISS10102'!K81 -> 91 | ... O25: ='ISS10102'!P81 -> 11.755612 | Q25: ='ISS10102'!Q81 -> 12.110554 | R25: =+D25/F25 -> 1.64975 | T25: 2014 | U25: =+SUMIF(#REF!,T25,G:G) -> #REF!
F26: =SUM(F22:F25) -> 10999900000 | R26: =+D26/F26 -> 0 | T26: 2015 | U26: =+SUMIF(#REF!,T26,G:G) -> #REF!
A27: ='ISS10102'!A91 -> 482 | B27: ='ISS10102'!B91 -> 37167 | C27: ='ISS10102'!D91 -> 2000000000 | D27: ='ISS10102'!E91 -> 7976800000 | E27: ='ISS10102'!F91 -> 5976800000 | F27: ='ISS10102'!G91 -> 1999900000 | G27: ='ISS10102'!H91 -> 1944815051 | H27: ='ISS10102'!I91 -> 55084949 | I27: ='ISS10102'!J91 -> 37258 | J27: ='ISS10102'!K91 -> 91 | ... O27: ='ISS10102'!P91 -> 11.047809 | Q27: ='ISS10102'!Q91 -> 11.360727 | R27: =+D27/F27 -> 3.9885994 | T27: 2016 | U27: =+SUMIF(#REF!,T27,G:G) -> #REF!
A28: ='ISS10102'!A96 -> 483 | B28: ='ISS10102'!B96 -> 37174 | C28: ='ISS10102'!D96 -> 2000000000 | D28: ='ISS10102'!E96 -> 10082200000 | E28: ='ISS10102'!F96 -> 8082200000 | F28: ='ISS10102'!G96 -> 2000000000 | G28: ='ISS10102'!H96 -> 1950843886 | H28: ='ISS10102'!I96 -> 49156114 | I28: ='ISS10102'!J96 -> 37265 | J28: ='ISS10102'!K96 -> 91 | ... O28: ='ISS10102'!P96 -> 9.8582317 | Q28: ='ISS10102'!Q96 -> 10.106633 | R28: =+D28/F28 -> 5.0411 | T28: 2017 | U28: =+SUMIF(#REF!,T28,G:G) -> #REF!
A29: ='ISS10102'!A101 -> 484 | B29: ='ISS10102'!B101 -> 37181 | C29: ='ISS10102'!D101 -> 2000000000 | D29: ='ISS10102'!E101 -> 9931100000 | E29: ='ISS10102'!F101 -> 7931100000 | F29: ='ISS10102'!G101 -> 2000000000 | G29: ='ISS10102'!H101 -> 1960323996 | H29: ='ISS10102'!I101 -> 39676004 | I29: ='ISS10102'!J101 -> 37272 | J29: ='ISS10102'!K101 -> 91 | ... O29: ='ISS10102'!P101 -> 7.9570008 | Q29: ='ISS10102'!Q101 -> 8.1180466 | R29: =+D29/F29 -> 4.96555 | T29: 2018 | U29: =+SUMIF(#REF!,T29,G:G) -> #REF!
A30: ='ISS10102'!A106 -> 485 | B30: ='ISS10102'!B106 -> 37188 | C30: ='ISS10102'!D106 -> 2000000000 | D30: ='ISS10102'!E106 -> 2919200000 | E30: ='ISS10102'!F106 -> 919200000 | F30: ='ISS10102'!G106 -> 2000000000 | G30: ='ISS10102'!H106 -> 1958434024 | H30: ='ISS10102'!I106 -> 41565976 | I30: ='ISS10102'!J106 -> 37279 | J30: ='ISS10102'!K106 -> 91 | ... O30: ='ISS10102'!P106 -> 8.3360336 | Q30: ='ISS10102'!Q106 -> 8.5129584 | R30: =+D30/F30 -> 1.4596 | T30: 2019 | U30: =+SUMIF(#REF!,T30,G:G) -> #REF!
A31: ='ISS10102'!A111 -> 486 | B31: ='ISS10102'!B111 -> 37195 | C31: ='ISS10102'!D111 -> 2000000000 | D31: ='ISS10102'!E111 -> 5359000000 | E31: ='ISS10102'!F111 -> 3359000000 | F31: ='ISS10102'!G111 -> 1999900000 | G31: ='ISS10102'!H111 -> 1961387440 | H31: ='ISS10102'!I111 -> 38512560 | I31: ='ISS10102'!J111 -> 37286 | J31: ='ISS10102'!K111 -> 91 | ... O31: ='ISS10102'!P111 -> 7.724059 | Q31: ='ISS10102'!Q111 -> 7.8757237 | R31: =+D31/F31 -> 2.679634 | T31: 2020 | U31: =+SUMIF(#REF!,T31,G:G) -> #REF!
F32: =SUM(F27:F31) -> 9999800000 | R32: =+D32/F32 -> 0 | T32: 2021 | U32: =+SUMIF(#REF!,T32,G:G) -> #REF!
A33: ='ISS10102'!A121 -> 487 | B33: ='ISS10102'!B121 -> 37202 | C33: ='ISS10102'!D121 -> 2000000000 | D33: ='ISS10102'!E121 -> 4897400000 | E33: ='ISS10102'!F121 -> 2897400000 | F33: ='ISS10102'!G121 -> 1999900000 | G33: ='ISS10102'!H121 -> 1963564342 | H33: ='ISS10102'!I121 -> 36335658 | I33: ='ISS10102'!J121 -> 37293 | J33: ='ISS10102'!K121 -> 91 | ... O33: ='ISS10102'!P121 -> 7.2874606 | Q33: ='ISS10102'!Q121 -> 7.4223147 | R33: =+D33/F33 -> 2.4488224 | T33: 2022 | U33: =+SUMIF(#REF!,T33,G:G) -> #REF!
A34: ='ISS10102'!A126 -> 488 | B34: ='ISS10102'!B126 -> 37209 | C34: ='ISS10102'!D126 -> 2000000000 | D34: ='ISS10102'!E126 -> 7030600000 | E34: ='ISS10102'!F126 -> 5030600000 | F34: ='ISS10102'!G126 -> 1999900000 | G34: ='ISS10102'!H126 -> 1965227616 | H34: ='ISS10102'!I126 -> 34672384 | I34: ='ISS10102'!J126 -> 37300 | J34: ='ISS10102'!K126 -> 91 | ... O34: ='ISS10102'!P126 -> 6.9538753 | Q34: ='ISS10102'!Q126 -> 7.076562 | R34: =+D34/F34 -> 3.5154758 | U34: =+SUMIF(#REF!,T34,G:G) -> #REF!
A35: ='ISS10102'!A131 -> 489 | B35: ='ISS10102'!B131 -> 37216 | C35: ='ISS10102'!D131 -> 3000000000 | D35: ='ISS10102'!E131 -> 9919200000 | E35: ='ISS10102'!F131 -> 6919200000 | F35: ='ISS10102'!G131 -> 3000000000 | G35: ='ISS10102'!H131 -> 2950319502 | H35: ='ISS10102'!I131 -> 49680498 | I35: ='ISS10102'!J131 -> 37307 | J35: ='ISS10102'!K131 -> 91 | ... O35: ='ISS10102'!P131 -> 6.6422644 | Q35: ='ISS10102'!Q131 -> 6.7541136 | R35: =+D35/F35 -> 3.3064 | U35: =+SUMIF(#REF!,T35,G:G) -> #REF!
A36: ='ISS10102'!A136 -> 490 | B36: ='ISS10102'!B136 -> 37223 | C36: ='ISS10102'!D136 -> 3000000000 | D36: ='ISS10102'!E136 -> 5436600000 | E36: ='ISS10102'!F136 -> 2436600000 | F36: ='ISS10102'!G136 -> 3000000000 | G36: ='ISS10102'!H136 -> 2950756509 | H36: ='ISS10102'!I136 -> 49243491 | I36: ='ISS10102'!J136 -> 37314 | J36: ='ISS10102'!K136 -> 91 | ... O36: ='ISS10102'!P136 -> 6.5838367 | Q36: ='ISS10102'!Q136 -> 6.6937106 | R36: =+D36/F36 -> 1.8122 | U36: =+SUMIF(#REF!,T36,G:G) -> #REF!
F37: =SUM(F33:F36) -> 9999800000 | R37: =+D37/F37 -> 0 | U37: =+SUMIF(#REF!,T37,G:G) -> #REF!
A38: ='ISS10102'!A146 -> 491 | B38: ='ISS10102'!B146 -> 37230 | C38: ='ISS10102'!D146 -> 3000000000 | D38: ='ISS10102'!E146 -> 9665700000 | E38: ='ISS10102'!F146 -> 6665700000 | F38: ='ISS10102'!G146 -> 3000000000 | G38: ='ISS10102'!H146 -> 2953689106 | H38: ='ISS10102'!I146 -> 46310894 | I38: ='ISS10102'!J146 -> 37321 | J38: ='ISS10102'!K146 -> 91 | ... O38: ='ISS10102'!P146 -> 6.1917496 | Q38: ='ISS10102'!Q146 -> 6.28883 | R38: =+D38/F38 -> 3.2219 | U38: =+SUMIF(#REF!,T38,G:G) -> #REF!
A39: ='ISS10102'!A151 -> 492 | B39: ='ISS10102'!B151 -> 37237 | C39: ='ISS10102'!D151 -> 3000000000 | D39: ='ISS10102'!E151 -> 7214300000 | E39: ='ISS10102'!F151 -> 4214300000 | F39: ='ISS10102'!G151 -> 2999900000 | G39: ='ISS10102'!H151 -> 2958084326 | H39: ='ISS10102'!I151 -> 41815674 | I39: ='ISS10102'!J151 -> 37328 | J39: ='ISS10102'!K151 -> 91 | ... O39: ='ISS10102'!P151 -> 5.5909267 | Q39: ='ISS10102'!Q151 -> 5.6699604 | R39: =+D39/F39 -> 2.4048468 | U39: =+SUMIF(#REF!,T39,G:G) -> #REF!
A40: ='ISS10102'!A156 -> 493 | B40: ='ISS10102'!B156 -> 37244 | C40: ='ISS10102'!D156 -> 3000000000 | D40: ='ISS10102'!E156 -> 4718200000 | E40: ='ISS10102'!F156 -> 1718200000 | F40: ='ISS10102'!G156 -> 3000000000 | G40: ='ISS10102'!H156 -> 2958123874 | H40: ='ISS10102'!I156 -> 41876126 | I40: ='ISS10102'!J156 -> 37335 | J40: ='ISS10102'!K156 -> 91 | ... O40: ='ISS10102'!P156 -> 5.5988227 | Q40: ='ISS10102'!Q156 -> 5.6780814 | R40: =+D40/F40 -> 1.5727333 | U40: =+SUMIF(#REF!,T40,G:G) -> #REF!
A41: ='ISS10102'!A161 -> 494 | B41: ='ISS10102'!B161 -> 37252 | C41: ='ISS10102'!D161 -> 2000000000 | D41: ='ISS10102'!E161 -> 4074800000 | E41: ='ISS10102'!F161 -> 2074800000 | F41: ='ISS10102'!G161 -> 2000000000 | G41: ='ISS10102'!H161 -> 1972695240 | H41: ='ISS10102'!I161 -> 27304760 | I41: ='ISS10102'!J161 -> 37343 | J41: ='ISS10102'!K161 -> 91 | ... O41: ='ISS10102'!P161 -> 5.4759546 | Q41: ='ISS10102'!Q161 -> 5.5517492 | R41: =+D41/F41 -> 2.0374 | U41: =+SUMIF(#REF!,T41,G:G) -> #REF!
F42: =SUM(F38:F41) -> 10999900000 | R42: =+D42/F42 -> 0 | U42: =+SUMIF(#REF!,T42,G:G) -> #REF!
...

Sheet maturities - 182
A2: Ref:ISS9899. WK3
A3: worksheet b
A4: - | B4: - | C4: - | D4: - | E4: - | F4: - | G4: - | H4: - | I4: - | J4: - | K4: - | L4: - | M4: - | N4: - | O4: -
A5: Auction | B5: Issue date | C5: Amount offered | D5: Total bids | E5: Over/(Under) | F5: Face Value of | G5: Cost Value | H5: Interest due | I5: Date due | J5: Duration | K5: Implicit annual | L5: Clearing | M5: Lowest | N5: Weighted | O5: Average | P5: Money Market | Q5: Annualised | R5: Rejected Amount | S5: Bid-to-cover
A6: No | C6: in | D6: (Competitive & | E6: Subscribed | F6: issues | K6: interest rate | L6: factor | M6: factor | N6: Average | O6: Discount | Q6: yield
C7: Auction | D7: Uncompetitive) | L7: (%) | M7: (%) | N7: Price | O7: factor
B8: (1) | C8: (1a) | D8: (1b) | F8: (2) | G8: (3) | H8: (4) | I8: (5) | J8: (6) | K8: -9 | L8: -10 | M8: -11 | N8: (12) | O8: (13)
A9: - | B9: - | C9: - | D9: - | E9: - | F9: - | G9: - | H9: - | I9: - | J9: - | K9: - | L9: - | M9: - | N9: - | O9: - | Q9: -
A10: 469 | B10: 37076 | C10: ='ISS10102'!D12 -> 1500000000 | D10: ='ISS10102'!E12 -> 2670000000 | E10: ='ISS10102'!F12 -> 1170000000 | F10: ='ISS10102'!G12 -> 1500000000 | G10: ='ISS10102'!H12 -> 1440153500 | H10: ='ISS10102'!I12 -> 59846500 | I10: ='ISS10102'!J12 -> 37259 | J10: ='ISS10102'!K12 -> 182 | M10: ='ISS10102'!N12 -> 7.621 | N10: ='ISS10102'!O12 -> 96.010233 | O10: ='ISS10102'!P12 -> 8.0014551 | Q10: =((100-N10)/N10*(365/182))*100 -> 8.3339607 | R10: =((100-O10)/O10*(365/182))*100 -> 2305.8628 | AA10: =2+1.5+1.5+1.5+1.5+1.5+1.5+2+2+2.5+3.5+3.5+3.5+3.4+3+3+3+1.5+11.5+11+10.99+9.99+9.99+10.99+10.99+8.99+11 -> 137.34
A11: =A10+1 -> 470 | B11: =B10+7 -> 37083 | C11: ='ISS10102'!D17 -> 2000000000 | D11: ='ISS10102'!E17 -> 2030000000 | E11: ='ISS10102'!F17 -> 30000000 | F11: ='ISS10102'!G17 -> 2000000000 | G11: ='ISS10102'!H17 -> 1895843600 | H11: ='ISS10102'!I17 -> 104156400 | I11: ='ISS10102'!J17 -> 37266 | J11: ='ISS10102'!K17 -> 182 | M11: ='ISS10102'!N17 -> 7.85 | N11: ='ISS10102'!O17 -> 94.79218 | O11: ='ISS10102'!P17 -> 10.444254 | Q11: =((100-N11)/N11*(365/182))*100 -> 11.018055 | R11: =((100-O11)/O11*(365/182))*100 -> 1719.6398
A12: =A11+1 -> 471 | B12: =B11+7 -> 37090 | C12: ='ISS10102'!D22 -> 2000000000 | D12: ='ISS10102'!E22 -> 3088900000 | E12: ='ISS10102'!F22 -> 1088900000 | F12: ='ISS10102'!G22 -> 2000000000 | G12: ='ISS10102'!H22 -> 1878252919 | H12: ='ISS10102'!I22 -> 121747081 | I12: ='ISS10102'!J22 -> 37273 | J12: ='ISS10102'!K22 -> 182 | M12: ='ISS10102'!N22 -> 11.03 | N12: ='ISS10102'!O22 -> 93.912646 | O12: ='ISS10102'!P22 -> 12.208155 | Q12: =((100-N12)/N12*(365/182))*100 -> 12.999479 | R12: =((100-O12)/O12*(365/182))*100 -> 1442.2004
A13: =A12+1 -> 472 | B13: =B12+7 -> 37097 | C13: ='ISS10102'!D27 -> 4000000000 | D13: ='ISS10102'!E27 -> 4000000000 | E13: ='ISS10102'!F27 -> 0 | F13: ='ISS10102'!G27 -> 4000000000 | G13: ='ISS10102'!H27 -> 3676427332 | H13: ='ISS10102'!I27 -> 323572668 | I13: ='ISS10102'!J27 -> 37280 | J13: ='ISS10102'!K27 -> 182 | M13: ='ISS10102'!N27 -> 9.999 | N13: ='ISS10102'!O27 -> 91.910683 | O13: ='ISS10102'!P27 -> 16.22308 | Q13: =((100-N13)/N13*(365/182))*100 -> 17.650919 | R13: =((100-O13)/O13*(365/182))*100 -> 1035.6489
B15: Total July 2001 | C15: =SUM(C10:C13) -> 9500000000 | D15: =SUM(D10:D13) -> 11788900000 | E15: =SUM(E10:E13) -> 2288900000 | F15: =SUM(F10:F13) -> 9500000000 | G15: =SUM(G10:G13) -> 8890677351 | H15: =SUM(H10:H13) -> 609322649 | N15: =AVERAGEA(N10:N13) -> 94.156436 | O15: =AVERAGEA(O10:O13) -> 11.719236 | Q15: =AVERAGEA(Q10:Q13) -> 12.500603 | R15: =((100-O15)/O15*(365/182))*100 -> 1510.7349
W16: 2001 | X16: =+SUMIF(#REF!,W16,G:G) -> #REF!
A17: =A13+1 -> 473 | B17: =B13+7 -> 37104 | C17: ='ISS10102'!D37 -> 4000000000 | D17: ='ISS10102'!E37 -> 8279400000 | E17: ='ISS10102'!F37 -> 4279400000 | F17: ='ISS10102'!G37 -> 4000000000 | G17: ='ISS10102'!H37 -> 3670506802 | H17: ='ISS10102'!I37 -> 329493198 | I17: ='ISS10102'!J37 -> 37287 | J17: ='ISS10102'!K37 -> 182 | M17: ='ISS10102'!N37 -> 13.116 | N17: ='ISS10102'!O37 -> 91.76267 | O17: ='ISS10102'!P37 -> 16.51992 | Q17: =((100-N17)/N17*(365/182))*100 -> 18.002876 | R17: =((100-O17)/O17*(365/182))*100 -> 1013.4362 | W17: 2002 | X17: =+SUMIF(#REF!,W17,G:G) -> #REF!
A18: =A17+1 -> 474 | B18: =B17+7 -> 37111 | C18: ='ISS10102'!D42 -> 4000000000 | D18: ='ISS10102'!E42 -> 6417600000 | E18: ='ISS10102'!F42 -> 2417600000 | F18: ='ISS10102'!G42 -> 4000000000 | G18: ='ISS10102'!H42 -> 3670675212 | H18: ='ISS10102'!I42 -> 329324788 | I18: ='ISS10102'!J42 -> 37294 | J18: ='ISS10102'!K42 -> 182 | M18: ='ISS10102'!N42 -> 14.038 | N18: ='ISS10102'!O42 -> 91.76688 | O18: ='ISS10102'!P42 -> 16.511476 | Q18: =((100-N18)/N18*(365/182))*100 -> 17.992849 | R18: =((100-O18)/O18*(365/182))*100 -> 1014.057 | W18: 2003 | X18: =+SUMIF(#REF!,W18,G:G) -> #REF!
A19: =A18+1 -> 475 | B19: =B18+7 -> 37118 | C19: ='ISS10102'!D47 -> 4000000000 | D19: ='ISS10102'!E47 -> 9595200000 | E19: ='ISS10102'!F47 -> 5595200000 | F19: ='ISS10102'!G47 -> 4000000000 | G19: ='ISS10102'!H47 -> 3683572728 | H19: ='ISS10102'!I47 -> 316427272 | I19: =I18+7 -> 37301 | J19: ='ISS10102'!K47 -> 182 | M19: ='ISS10102'!N47 -> 15.673 | N19: ='ISS10102'!O47 -> 92.089318 | O19: ='ISS10102'!P47 -> 15.864829 | Q19: =((100-N19)/N19*(365/182))*100 -> 17.227654 | R19: =((100-O19)/O19*(365/182))*100 -> 1063.5641 | W19: 2004 | X19: =+SUMIF(#REF!,W19,G:G) -> #REF!
A20: =A19+1 -> 476 | B20: =B19+7 -> 37125 | C20: ='ISS10102'!D52 -> 4000000000 | D20: ='ISS10102'!E52 -> 7640300000 | E20: ='ISS10102'!F52 -> 3640300000 | F20: ='ISS10102'!G52 -> 4000000000 | G20: ='ISS10102'!H52 -> 3684876740 | H20: ='ISS10102'!I52 -> 315123260 | I20: =I19+7 -> 37308 | J20: ='ISS10102'!K52 -> 182 | M20: ='ISS10102'!N52 -> 14.941 | N20: ='ISS10102'!O52 -> 92.121918 | O20: ='ISS10102'!P52 -> 15.799449 | Q20: =((100-N20)/N20*(365/182))*100 -> 17.150586 | R20: =((100-O20)/O20*(365/182))*100 -> 1068.7951 | W20: 2005 | X20: =+SUMIF(#REF!,W20,G:G) -> #REF!
A21: =A20+1 -> 477 | B21: =B20+7 -> 37132 | C21: ='ISS10102'!D57 -> 3000000000 | D21: ='ISS10102'!E57 -> 6817700000 | E21: ='ISS10102'!F57 -> 3817700000 | F21: ='ISS10102'!G57 -> 3000000000 | G21: ='ISS10102'!H57 -> 2772024660 | H21: ='ISS10102'!I57 -> 227975340 | I21: =I20+7 -> 37315 | J21: ='ISS10102'!K57 -> 182 | M21: ='ISS10102'!N57 -> 14.379 | N21: ='ISS10102'!O57 -> 92.400822 | O21: ='ISS10102'!P57 -> 15.24011 | Q21: =((100-N21)/N21*(365/182))*100 -> 16.493479 | R21: =((100-O21)/O21*(365/182))*100 -> 1115.3824 | W21: 2006 | X21: =+SUMIF(#REF!,W21,G:G) -> #REF!
W22: 2007 | X22: =+SUMIF(#REF!,W22,G:G) -> #REF!
B23: Total Aug 2001 | C23: =SUM(C17:C21) -> 19000000000 | D23: =SUM(D17:D21) -> 38750200000 | E23: =SUM(E17:E21) -> 19750200000 | F23: =SUM(F17:F21) -> 19000000000 | G23: =SUM(G17:G21) -> 17481656142 | H23: =SUM(H17:H21) -> 1518343858 | N23: =AVERAGEA(N17:N21) -> 92.028322 | O23: =AVERAGEA(O17:O21) -> 15.987157 | Q23: =AVERAGEA(Q17:Q21) -> 17.373489 | R23: =((100-O23)/O23*(365/182))*100 -> 1053.8916 | W23: 2008 | X23: =+SUMIF(#REF!,W23,G:G) -> #REF!
W24: 2009 | X24: =+SUMIF(#REF!,W24,G:G) -> #REF!
A25: =A21+1 -> 478 | B25: =B21+7 -> 37139 | C25: ='ISS10102'!D67 -> 4000000000 | D25: ='ISS10102'!E67 -> 4000000000 | E25: ='ISS10102'!F67 -> 0 | F25: ='ISS10102'!G67 -> 4000000000 | G25: ='ISS10102'!H67 -> 3697377278 | H25: =F25-G25 -> 302622722 | I25: =I21+7 -> 37322 | J25: ='ISS10102'!K67 -> 182 | M25: 14 | N25: ='ISS10102'!O67 -> 92.434432 | O25: ='ISS10102'!P67 -> 15.172705 | Q25: =((100-N25)/N25*(365/182))*100 -> 16.41456 | R25: =((100-O25)/O25*(365/182))*100 -> 1121.2284 | W25: 2010 | X25: =+SUMIF(#REF!,W25,G:G) -> #REF!
A26: 479 | B26: =B25+7 -> 37146 | C26: ='ISS10102'!D72 -> 4000000000 | D26: ='ISS10102'!E72 -> 10703100000 | E26: ='ISS10102'!F72 -> 6703100000 | F26: ='ISS10102'!G72 -> 3999900000 | G26: ='ISS10102'!H72 -> 3719315125 | H26: =F26-G26 -> 280584875 | I26: =I25+7 -> 37329 | J26: ='ISS10102'!K72 -> 182 | M26: 13 | N26: ='ISS10102'!O72 -> 92.985203 | O26: ='ISS10102'!P72 -> 14.068137 | Q26: =((100-N26)/N26*(365/182))*100 -> 15.129437 | R26: =((100-O26)/O26*(365/182))*100 -> 1225.0085 | W26: 2011 | X26: =+SUMIF(#REF!,W26,G:G) -> #REF!
A27: 480 | B27: =B26+7 -> 37153 | C27: ='ISS10102'!D77 -> 4000000000 | D27: ='ISS10102'!E77 -> 6831500000 | E27: ='ISS10102'!F77 -> 2831500000 | F27: ='ISS10102'!G77 -> 4000000000 | G27: ='ISS10102'!H77 -> 3719466530 | H27: =F27-G27 -> 280533470 | I27: =I26+7 -> 37336 | J27: ='ISS10102'!K77 -> 182 | M27: ='ISS10102'!N77 -> 13 | N27: ='ISS10102'!O77 -> 92.986663 | O27: ='ISS10102'!P77 -> 14.065208 | Q27: =((100-N27)/N27*(365/182))*100 -> 15.126049 | R27: =((100-O27)/O27*(365/182))*100 -> 1225.3054 | W27: 2012 | X27: =+SUMIF(#REF!,W27,G:G) -> #REF!
A28: 481 | B28: =B27+7 -> 37160 | C28: ='ISS10102'!D82 -> 3000000000 | D28: ='ISS10102'!E82 -> 7517600000 | E28: ='ISS10102'!F82 -> 4517600000 | F28: ='ISS10102'!G82 -> 3000000000 | G28: ='ISS10102'!H82 -> 2804464804 | H28: =F28-G28 -> 195535196 | I28: =I27+7 -> 37343 | J28: ='ISS10102'!K82 -> 182 | M28: ='ISS10102'!N82 -> 12.234 | N28: ='ISS10102'!O82 -> 93.48216 | O28: ='ISS10102'!P82 -> 13.071492 | Q28: =((100-N28)/N28*(365/182))*100 -> 13.982873 | R28: =((100-O28)/O28*(365/182))*100 -> 1333.7012 | W28: 2013 | X28: =+SUMIF(#REF!,W28,G:G) -> #REF!
W29: 2014 | X29: =+SUMIF(#REF!,W29,G:G) -> #REF!
B30: Total Sep 2001 | C30: =SUM(C25:C28) -> 15000000000 | D30: =SUM(D25:D28) -> 29052200000 | E30: =SUM(E25:E28) -> 14052200000 | F30: =SUM(F25:F28) -> 14999900000 | G30: =SUM(G25:G28) -> 13940623737 | H30: =SUM(H25:H28) -> 1059276263 | N30: =AVERAGEA(N25:N28) -> 92.972115 | O30: =AVERAGEA(O25:O28) -> 14.094386 | Q30: =AVERAGEA(Q25:Q28) -> 15.16323 | R30: =((100-O30)/O30*(365/182))*100 -> 1222.3536 | W30: 2015 | X30: =+SUMIF(#REF!,W30,G:G) -> #REF!
W31: 2016 | X31: =+SUMIF(#REF!,W31,G:G) -> #REF!
A32: 482 | B32: 37167 | C32: ='ISS10102'!D92 -> 3000000000 | D32: ='ISS10102'!E92 -> 7190900000 | E32: ='ISS10102'!F92 -> 4190900000 | F32: ='ISS10102'!G92 -> 2999900000 | G32: ='ISS10102'!H92 -> 2814589727 | H32: =F32-G32 -> 185310273 | I32: =I28+7 -> 37350 | J32: ='ISS10102'!K92 -> 182 | M32: ='ISS10102'!N92 -> 11.766 | N32: ='ISS10102'!O92 -> 93.822785 | O32: ='ISS10102'!P92 -> 12.388371 | Q32: =((100-N32)/N32*(365/182))*100 -> 13.204011 | R32: =((100-O32)/O32*(365/182))*100 -> 1418.3031 | W32: 2017 | X32: =+SUMIF(#REF!,W32,G:G) -> #REF!
A33: =A32+1 -> 483 | B33: =B32+7 -> 37174 | C33: ='ISS10102'!D97 -> 3000000000 | D33: ='ISS10102'!E97 -> 7100500000 | E33: ='ISS10102'!F97 -> 4100500000 | F33: ='ISS10102'!G97 -> 2999900000 | G33: ='ISS10102'!H97 -> 2826262928 | H33: =F33-G33 -> 173637072 | I33: =B33+J33+1 -> 37357 | J33: ='ISS10102'!K97 -> 182 | M33: ='ISS10102'!N97 -> 11.205 | N33: ='ISS10102'!O97 -> 94.211905 | O33: ='ISS10102'!P97 -> 11.607993 | Q33: =((100-N33)/N33*(365/182))*100 -> 12.321154 | R33: =((100-O33)/O33*(365/182))*100 -> 1527.1346 | W33: 2018 | X33: =+SUMIF(#REF!,W33,G:G) -> #REF!
A34: =A33+1 -> 484 | B34: =B33+7 -> 37181 | C34: ='ISS10102'!D102 -> 3000000000 | D34: ='ISS10102'!E102 -> 12000600000 | E34: ='ISS10102'!F102 -> 9000600000 | F34: ='ISS10102'!G102 -> 3000000000 | G34: ='ISS10102'!H102 -> 2846426314 | H34: =F34-G34 -> 153573686 | I34: =B34+J34+1 -> 37364 | J34: ='ISS10102'!K102 -> 182 | M34: ='ISS10102'!N102 -> 9.001 | N34: ='ISS10102'!O102 -> 94.880877 | O34: ='ISS10102'!P102 -> 10.266373 | Q34: =((100-N34)/N34*(365/182))*100 -> 10.820276 | R34: =((100-O34)/O34*(365/182))*100 -> 1752.9102 | W34: 2019 | X34: =+SUMIF(#REF!,W34,G:G) -> #REF!
A35: =A34+1 -> 485 | B35: =B34+7 -> 37188 | C35: ='ISS10102'!D107 -> 3000000000 | D35: ='ISS10102'!E107 -> 4935300000 | E35: ='ISS10102'!F107 -> 1935300000 | F35: ='ISS10102'!G107 -> 2999900000 | G35: ='ISS10102'!H107 -> 2854346884 | H35: =F35-G35 -> 145553116 | I35: =B35+J35+1 -> 37371 | J35: ='ISS10102'!K107 -> 182 | M35: ='ISS10102'!N107 -> 8.686 | N35: ='ISS10102'!O107 -> 95.148068 | O35: ='ISS10102'!P107 -> 9.7305235 | Q35: =((100-N35)/N35*(365/182))*100 -> 10.226717 | R35: =((100-O35)/O35*(365/182))*100 -> 1860.4851 | W35: 2020 | X35: =+SUMIF(#REF!,W35,G:G) -> #REF!
A36: =A35+1 -> 486 | B36: =B35+7 -> 37195 | C36: ='ISS10102'!D112 -> 2000000000 | D36: ='ISS10102'!E112 -> 5738800000 | E36: ='ISS10102'!F112 -> 3738800000 | F36: ='ISS10102'!G112 -> 2000000000 | G36: ='ISS10102'!H112 -> 1906225848 | H36: =F36-G36 -> 93774152 | I36: =B36+J36+1 -> 37378 | J36: ='ISS10102'!K112 -> 182 | M36: ='ISS10102'!N112 -> 9.071 | N36: ='ISS10102'!O112 -> 95.311292 | O36: ='ISS10102'!P112 -> 9.4031773 | Q36: =((100-N36)/N36*(365/182))*100 -> 9.8657537 | R36: =((100-O36)/O36*(365/182))*100 -> 1932.2344 | W36: 2021 | X36: =+SUMIF(#REF!,W36,G:G) -> #REF!
W37: 2022 | X37: =+SUMIF(#REF!,W37,G:G) -> #REF!
B38: Total Oct 2001 | C38: =SUM(C32:C36) -> 14000000000 | D38: =SUM(D32:D36) -> 36966100000 | E38: =SUM(E32:E36) -> 22966100000 | F38: =SUM(F32:F36) -> 13999700000 | G38: =SUM(G32:G36) -> 13247851701 | H38: =SUM(H32:H36) -> 751848299 | N38: =AVERAGEA(N32:N36) -> 94.674985 | O38: =AVERAGEA(O32:O36) -> 10.679288 | Q38: =AVERAGEA(Q32:Q36) -> 11.287582 | R38: =((100-O38)/O38*(365/182))*100 -> 1677.3797
F39: =SUM(F32:F35) -> 11999700000
A40: =A36+1 -> 487 | B40: =B36+7 -> 37202 | C40: ='ISS10102'!D122 -> 3000000000 | D40: ='ISS10102'!E122 -> 5866400000 | E40: ='ISS10102'!F122 -> 2866400000 | F40: ='ISS10102'!G122 -> 3000000000 | G40: ='ISS10102'!H122 -> 2865331424 | H40: =F40-G40 -> 134668576 | I40: =B40+J40+1 -> 37385 | J40: ='ISS10102'!K122 -> 182 | M40: ='ISS10102'!N122 -> 3.61 | N40: ='ISS10102'!O122 -> 95.511047 | O40: ='ISS10102'!P122 -> 9.0025696 | Q40: =((100-N40)/N40*(365/182))*100 -> 9.4256841 | R40: =((100-O40)/O40*(365/182))*100 -> 2027.1417
A41: =A40+1 -> 488 | B41: =B40+7 -> 37209 | C41: ='ISS10102'!D127 -> 4000000000 | D41: ='ISS10102'!E127 -> 11313500000 | E41: ='ISS10102'!F127 -> 7313500000 | F41: ='ISS10102'!G127 -> 4000000000 | G41: ='ISS10102'!H127 -> 3828537535 | H41: =F41-G41 -> 171462465 | I41: =B41+J41+1 -> 37392 | J41: ='ISS10102'!K127 -> 182 | M41: ='ISS10102'!N127 -> 8.251 | N41: ='ISS10102'!O127 -> 95.713438 | O41: ='ISS10102'!P127 -> 8.5966758 | Q41: =((100-N41)/N41*(365/182))*100 -> 8.9816811 | R41: =((100-O41)/O41*(365/182))*100 -> 2132.3226
A42: =A41+1 -> 489 | B42: =B41+7 -> 37216 | C42: ='ISS10102'!D132 -> 4000000000 | D42: ='ISS10102'!E132 -> 9885000000 | E42: ='ISS10102'!F132 -> 5885000000 | F42: ='ISS10102'!G132 -> 4000000000 | G42: ='ISS10102'!H132 -> 3833158200 | H42: =F42-G42 -> 166841800 | I42: =B42+J42+1 -> 37399 | J42: ='ISS10102'!K132 -> 182 | M42: ='ISS10102'!N132 -> 8.253 | N42: ='ISS10102'!O132 -> 95.828955 | O42: ='ISS10102'!P132 -> 8.3650078 | Q42: =((100-N42)/N42*(365/182))*100 -> 8.7291026 | R42: =((100-O42)/O42*(365/182))*100 -> 2196.9313
...

Sheet maturities - 273
A2: Ref:ISS9899. WK3
A3: worksheet b
A4: - | B4: - | D4: - | E4: - | F4: - | G4: - | H4: - | I4: - | J4: - | K4: - | L4: - | M4: - | N4: - | O4: - | P4: - | Q4: -
A5: Auction | B5: Issue date | D5: Amount offered | E5: Total bids | F5: Over/(Under) | G5: Face Value of | H5: Cost Value | I5: Interest due | J5: Date due | K5: Duration | L5: Implicit annual | M5: Clearing | N5: Lowest | O5: Weighted | P5: Average | Q5: Annualised
A6: No | D6: in | E6: (Competitive & | F6: Subscribed | G6: issues | L6: interest rate | M6: factor | N6: factor | O6: Average | P6: Discount | Q6: yield
D7: Auction | E7: Uncompetitive) | M7: (%) | N7: (%) | O7: Price | P7: factor
B8: (1) | D8: (1a) | E8: (1b) | G8: (2) | H8: (3) | I8: (4) | J8: (5) | K8: (6) | L8: (9) | M8: (10) | N8: (11) | O8: (12) | P8: (13)
A9: - | B9: - | D9: - | E9: - | F9: - | G9: - | H9: - | I9: - | J9: - | K9: - | L9: - | M9: - | N9: - | O9: - | P9: - | Q9: -
A10: 469 | B10: 37076 | D10: ='ISS10102'!D13 -> 4000000000 | E10: ='ISS10102'!E13 -> 5477000000 | F10: ='ISS10102'!F13 -> 1477000000 | G10: ='ISS10102'!G13 -> 4000000000 | H10: ='ISS10102'!H13 -> 3698699840 | I10: ='ISS10102'!I13 -> 301300160 | J10: =B10+K10+1 -> 37350 | K10: ='ISS10102'!K13 -> 273 | N10: ='ISS10102'!N13 -> 9.426 | O10: ='ISS10102'!O13 -> 92.467496 | P10: ='ISS10102'!P13 -> 10.07093 | Q10: =((100-O10)/O10*(365/273))*100 -> 10.891319
A11: =A10+1 -> 470 | B11: =B10+7 -> 37083 | D11: ='ISS10102'!D18 -> 5000000000 | E11: ='ISS10102'!E18 -> 5000000000 | F11: ='ISS10102'!F18 -> 0 | G11: ='ISS10102'!G18 -> 5000000000 | H11: ='ISS10102'!H18 -> 4570702500 | I11: ='ISS10102'!I18 -> 429297500 | J11: =J10+7 -> 37357 | K11: ='ISS10102'!K18 -> 273 | N11: ='ISS10102'!N18 -> 10.629 | O11: ='ISS10102'!O18 -> 91.41405 | P11: ='ISS10102'!P18 -> 11.479384 | Q11: =((100-O11)/O11*(365/273))*100 -> 12.55757
A12: =A11+1 -> 471 | B12: =B11+7 -> 37090 | D12: ='ISS10102'!D23 -> 5000000000 | E12: ='ISS10102'!E23 -> 5000000000 | F12: ='ISS10102'!F23 -> 0 | G12: ='ISS10102'!G23 -> 5000000000 | H12: ='ISS10102'!H23 -> 4483755000 | I12: ='ISS10102'!I23 -> 516245000 | J12: =J11+7 -> 37364 | K12: ='ISS10102'!K23 -> 273 | N12: ='ISS10102'!N23 -> 11.848 | O12: ='ISS10102'!O23 -> 89.6751 | P12: ='ISS10102'!P23 -> 13.804353 | Q12: =((100-O12)/O12*(365/273))*100 -> 15.393742
A13: =A12+1 -> 472 | B13: =B12+7 -> 37097 | D13: ='ISS10102'!D28 -> 5000000000 | E13: ='ISS10102'!E28 -> 5000000000 | F13: ='ISS10102'!F28 -> 0 | G13: ='ISS10102'!G28 -> 5000000000 | H13: ='ISS10102'!H28 -> 4265972900 | I13: ='ISS10102'!I28 -> 734027100 | J13: =J12+7 -> 37371 | K13: ='ISS10102'!K28 -> 273 | N13: ='ISS10102'!N28 -> 12 | O13: ='ISS10102'!O28 -> 85.319458 | P13: ='ISS10102'!P28 -> 19.627831 | Q13: =((100-O13)/O13*(365/273))*100 -> 23.005105
B15: Total Jul 2001 | D15: =SUM(D10:D13) -> 19000000000 | E15: =SUM(E10:E13) -> 20477000000 | F15: =SUM(F10:F13) -> 1477000000 | G15: =SUM(G10:G13) -> 19000000000 | H15: =SUM(H10:H13) -> 17019130240 | I15: =SUM(I10:I13) -> 1980869760 | O15: =AVERAGEA(O10:O13) -> 89.719026 | P15: =AVERAGEA(P10:P13) -> 13.745625 | Q15: =AVERAGEA(Q10:Q13) -> 15.461934
A17: =A13+1 -> 473 | B17: =B13+7 -> 37104 | D17: ='ISS10102'!D38 -> 4000000000 | E17: ='ISS10102'!E38 -> 10723700000 | F17: ='ISS10102'!F38 -> 6723700000 | G17: ='ISS10102'!G38 -> 3999900000 | H17: ='ISS10102'!H38 -> 3411615570 | I17: ='ISS10102'!I38 -> 588284430 | J17: =J13+7 -> 37378 | K17: ='ISS10102'!K38 -> 273 | N17: ='ISS10102'!N38 -> 17.381 | O17: ='ISS10102'!O38 -> 85.292522 | P17: ='ISS10102'!P38 -> 19.663845 | Q17: =((100-O17)/O17*(365/273))*100 -> 23.054594
A18: =A17+1 -> 474 | B18: =B17+7 -> 37111 | D18: ='ISS10102'!D43 -> 6000000000 | E18: ='ISS10102'!E43 -> 10552200000 | F18: ='ISS10102'!F43 -> 4552200000 | G18: ='ISS10102'!G43 -> 6000000000 | H18: ='ISS10102'!H43 -> 5070862258 | I18: ='ISS10102'!I43 -> 929137742 | J18: =J17+7 -> 37385 | K18: ='ISS10102'!K43 -> 273 | N18: ='ISS10102'!N43 -> 18 | O18: ='ISS10102'!O43 -> 84.514371 | P18: ='ISS10102'!P43 -> 20.704229 | Q18: =((100-O18)/O18*(365/273))*100 -> 24.49788
A19: =A18+1 -> 475 | B19: =B18+7 -> 37118 | D19: ='ISS10102'!D48 -> 5000000000 | E19: ='ISS10102'!E48 -> 9401000000 | F19: ='ISS10102'!F48 -> 4401000000 | G19: ='ISS10102'!G48 -> 5000000000 | H19: ='ISS10102'!H48 -> 4213782060 | I19: ='ISS10102'!I48 -> 786217940 | J19: =J18+7 -> 37392 | K19: ='ISS10102'!K48 -> 273 | N19: ='ISS10102'!N48 -> 18.918 | O19: ='ISS10102'!O48 -> 84.275641 | P19: ='ISS10102'!P48 -> 21.02341 | Q19: =((100-O19)/O19*(365/273))*100 -> 24.94601
A20: =A19+1 -> 476 | B20: =B19+7 -> 37125 | D20: ='ISS10102'!D53 -> 5000000000 | E20: ='ISS10102'!E53 -> 14861900000 | F20: ='ISS10102'!F53 -> 9861900000 | G20: ='ISS10102'!G53 -> 4999900000 | H20: ='ISS10102'!H53 -> 4271361534 | I20: ='ISS10102'!I53 -> 728538466 | J20: =J19+7 -> 37399 | K20: ='ISS10102'!K53 -> 273 | N20: ='ISS10102'!N53 -> 17.381 | O20: ='ISS10102'!O53 -> 85.428939 | P20: ='ISS10102'!P53 -> 19.481455 | Q20: =((100-O20)/O20*(365/273))*100 -> 22.80428
A21: =A20+1 -> 477 | B21: =B20+7 -> 37132 | D21: ='ISS10102'!D58 -> 4000000000 | E21: ='ISS10102'!E58 -> 12127000000 | F21: ='ISS10102'!F58 -> 8127000000 | G21: ='ISS10102'!G58 -> 3999900000 | H21: ='ISS10102'!H58 -> 3461414160 | I21: ='ISS10102'!I58 -> 538485840 | J21: =J20+7 -> 37406 | K21: ='ISS10102'!K58 -> 273 | N21: ='ISS10102'!N58 -> 17.515 | O21: ='ISS10102'!O58 -> 86.537517 | P21: ='ISS10102'!P58 -> 17.99929 | Q21: =((100-O21)/O21*(365/273))*100 -> 20.799406
B23: Total Aug 2001 | D23: =SUM(D17:D21) -> 24000000000 | E23: =SUM(E17:E21) -> 57665800000 | F23: =SUM(F17:F21) -> 33665800000 | G23: =SUM(G17:G21) -> 23999700000 | H23: =SUM(H17:H21) -> 20429035582 | I23: =SUM(I17:I21) -> 3570664418 | O23: =AVERAGEA(O17:O21) -> 85.209798 | P23: =AVERAGEA(P17:P21) -> 19.774446 | Q23: =AVERAGEA(Q17:Q21) -> 23.220434
A25: =A21+1 -> 478 | B25: =B21+7 -> 37139 | D25: ='ISS10102'!D68 -> 5000000000 | E25: ='ISS10102'!E68 -> 4999800000 | F25: ='ISS10102'!F68 -> -200000 | G25: ='ISS10102'!G68 -> 4999800000 | H25: ='ISS10102'!H68 -> 4342526855 | I25: =G25-H25 -> 657273145 | J25: =J21+7 -> 37413 | K25: ='ISS10102'!K68 -> 273 | N25: 17 | O25: ='ISS10102'!O68 -> 86.854011 | P25: ='ISS10102'!P68 -> 17.576139 | Q25: =((100-O25)/O25*(365/273))*100 -> 20.236416
A26: =A25+1 -> 479 | B26: =B25+7 -> 37146 | D26: ='ISS10102'!D73 -> 5000000000 | E26: ='ISS10102'!E73 -> 16566000000 | F26: ='ISS10102'!F73 -> 11566000000 | G26: ='ISS10102'!G73 -> 5000000000 | H26: ='ISS10102'!H73 -> 4397456245 | I26: =G26-H26 -> 602543755 | J26: =J25+7 -> 37420 | K26: ='ISS10102'!K73 -> 273 | N26: ='ISS10102'!N73 -> 15.119 | O26: ='ISS10102'!O73 -> 87.949125 | P26: ='ISS10102'!P73 -> 16.111976 | Q26: =((100-O26)/O26*(365/273))*100 -> 18.319655
A27: =A26+1 -> 480 | B27: =B26+7 -> 37153 | D27: ='ISS10102'!D78 -> 5000000000 | E27: ='ISS10102'!E78 -> 12395200000 | F27: ='ISS10102'!F78 -> 7395200000 | G27: ='ISS10102'!G78 -> 4999700000 | H27: ='ISS10102'!H78 -> 4432431555 | I27: =G27-H27 -> 567268445 | J27: =J26+7 -> 37427 | K27: ='ISS10102'!K78 -> 273 | N27: ='ISS10102'!N78 -> 14.292 | O27: ='ISS10102'!O78 -> 88.65395 | P27: ='ISS10102'!P78 -> 15.169627 | Q27: =((100-O27)/O27*(365/273))*100 -> 17.111056
A28: =A27+1 -> 481 | B28: =B27+7 -> 37160 | D28: ='ISS10102'!D83 -> 4000000000 | E28: ='ISS10102'!E83 -> 11636000000 | F28: ='ISS10102'!F83 -> 7636000000 | G28: ='ISS10102'!G83 -> 3999900000 | H28: ='ISS10102'!H83 -> 3584442625 | I28: =G28-H28 -> 415457375 | J28: =J27+7 -> 37434 | K28: ='ISS10102'!K83 -> 273 | N28: ='ISS10102'!N83 -> 13.169 | O28: ='ISS10102'!O83 -> 89.613306 | P28: ='ISS10102'!P83 -> 13.886972 | Q28: =((100-O28)/O28*(365/273))*100 -> 15.496551
B30: Total Sep 2001 | D30: =SUM(D25:D28) -> 19000000000 | E30: =SUM(E25:E28) -> 45597000000 | F30: =SUM(F25:F28) -> 26597000000 | G30: =SUM(G25:G28) -> 18999400000 | H30: =SUM(H25:H28) -> 16756857280 | I30: =SUM(I25:I28) -> 2242542720 | J30: =SUM(J25:J28) -> 149694 | K30: =SUM(K25:K28) -> 1092 | O30: =AVERAGEA(O25:O28) -> 88.267598 | P30: =AVERAGEA(P25:P28) -> 15.686178 | Q30: =AVERAGEA(Q25:Q28) -> 17.790919
A32: =A28+1 -> 482 | B32: =B28+7 -> 37167 | D32: ='ISS10102'!D93 -> 4000000000 | E32: ='ISS10102'!E93 -> 8376000000 | F32: ='ISS10102'!F93 -> 4376000000 | G32: ='ISS10102'!G93 -> 3999900000 | H32: ='ISS10102'!H93 -> 3603379951 | I32: =G32-H32 -> 396520049 | J32: =J28+7 -> 37441 | K32: ='ISS10102'!K93 -> 273 | N32: ='ISS10102'!N93 -> 12.568 | O32: ='ISS10102'!O93 -> 90.086751 | P32: ='ISS10102'!P93 -> 13.253978 | Q32: =((100-O32)/O32*(365/273))*100 -> 14.712461
A33: =A32+1 -> 483 | B33: =B32+7 -> 37174 | D33: ='ISS10102'!D98 -> 4000000000 | E33: ='ISS10102'!E98 -> 9208000000 | F33: ='ISS10102'!F98 -> 5208000000 | G33: ='ISS10102'!G98 -> 4000000000 | H33: ='ISS10102'!H98 -> 3613052690 | I33: =G33-H33 -> 386947310 | J33: =B33+K33+1 -> 37448 | K33: ='ISS10102'!K98 -> 273 | N33: ='ISS10102'!N98 -> 12.16 | O33: ='ISS10102'!O98 -> 90.326317 | P33: ='ISS10102'!P98 -> 12.933678 | Q33: =((100-O33)/O33*(365/273))*100 -> 14.318837
A34: =A33+1 -> 484 | B34: =B33+7 -> 37181 | D34: ='ISS10102'!D103 -> 4000000000 | E34: ='ISS10102'!E103 -> 12281000000 | F34: ='ISS10102'!F103 -> 8281000000 | G34: ='ISS10102'!G103 -> 4000000000 | H34: ='ISS10102'!H103 -> 3628802660 | I34: =G34-H34 -> 371197340 | J34: =B34+K34+1 -> 37455 | K34: ='ISS10102'!K103 -> 273 | N34: ='ISS10102'!N103 -> 12 | O34: ='ISS10102'!O103 -> 90.720067 | P34: ='ISS10102'!P103 -> 12.407237 | Q34: =((100-O34)/O34*(365/273))*100 -> 13.676398
A35: =A34+1 -> 485 | B35: =B34+7 -> 37188 | D35: ='ISS10102'!D108 -> 4000000000 | E35: ='ISS10102'!E108 -> 5369500000 | F35: ='ISS10102'!F108 -> 1369500000 | G35: ='ISS10102'!G108 -> 4000000000 | H35: ='ISS10102'!H108 -> 3647779923 | I35: =G35-H35 -> 352220077 | J35: =B35+K35+1 -> 37462 | K35: ='ISS10102'!K108 -> 273 | N35: ='ISS10102'!N108 -> 8.666 | O35: ='ISS10102'!O108 -> 91.194498 | P35: ='ISS10102'!P108 -> 11.772924 | Q35: =((100-O35)/O35*(365/273))*100 -> 12.909687
A36: =A35+1 -> 486 | B36: =B35+7 -> 37195 | D36: ='ISS10102'!D113 -> 3000000000 | E36: ='ISS10102'!E113 -> 8260800000 | F36: ='ISS10102'!F113 -> 5260800000 | G36: ='ISS10102'!G113 -> 3000000000 | H36: ='ISS10102'!H113 -> 2768805482 | I36: =G36-H36 -> 231194518 | J36: =B36+K36+1 -> 37469 | K36: ='ISS10102'!K113 -> 273 | N36: ='ISS10102'!N113 -> 9.499 | O36: ='ISS10102'!O113 -> 92.293516 | P36: ='ISS10102'!P113 -> 10.303541 | Q36: =((100-O36)/O36*(365/273))*100 -> 11.163884
B38: Total Oct 2001 | D38: =SUM(D32:D36) -> 19000000000 | E38: =SUM(E32:E36) -> 43495300000 | F38: =SUM(F32:F36) -> 24495300000 | G38: =SUM(G32:G36) -> 18999900000 | H38: =SUM(H32:H36) -> 17261820706 | I38: =SUM(I32:I36) -> 1738079294 | O38: =AVERAGEA(O32:O36) -> 90.92423 | P38: =AVERAGEA(P32:P36) -> 12.134272 | Q38: =AVERAGEA(Q32:Q36) -> 13.356253
A40: =A36+1 -> 487 | B40: =B36+7 -> 37202 | D40: ='ISS10102'!D123 -> 4000000000 | E40: ='ISS10102'!E123 -> 9789600000 | F40: ='ISS10102'!F123 -> 5789600000 | G40: ='ISS10102'!G123 -> 4000000000 | H40: ='ISS10102'!H123 -> 3694062442 | I40: =G40-H40 -> 305937558 | J40: =B40+K40+1 -> 37476 | K40: ='ISS10102'!K123 -> 273 | N40: ='ISS10102'!N123 -> 9.499 | O40: ='ISS10102'!O123 -> 92.351561 | P40: ='ISS10102'!P123 -> 10.225935 | Q40: =((100-O40)/O40*(365/273))*100 -> 11.072834
A41: =A40+1 -> 488 | B41: =B40+7 -> 37209 | D41: ='ISS10102'!D128 -> 5000000000 | E41: ='ISS10102'!E128 -> 12591300000 | F41: ='ISS10102'!F128 -> 7591300000 | G41: ='ISS10102'!G128 -> 5000000000 | H41: ='ISS10102'!H128 -> 4626930920 | I41: =G41-H41 -> 373069080 | J41: =B41+K41+1 -> 37483 | K41: ='ISS10102'!K128 -> 273 | N41: ='ISS10102'!N128 -> 9.328 | O41: ='ISS10102'!O128 -> 92.538618 | P41: ='ISS10102'!P128 -> 9.9758399 | Q41: =((100-O41)/O41*(365/273))*100 -> 10.780191
A42: =A41+1 -> 489 | B42: =B41+7 -> 37216 | D42: ='ISS10102'!D133 -> 5000000000 | E42: ='ISS10102'!E133 -> 11940000000 | F42: ='ISS10102'!F133 -> 6940000000 | G42: ='ISS10102'!G133 -> 5000000000 | H42: ='ISS10102'!H133 -> 4620339900 | I42: =G42-H42 -> 379660100 | J42: =B42+K42+1 -> 37490 | K42: ='ISS10102'!K133 -> 273 | N42: ='ISS10102'!N133 -> 9.85 | O42: ='ISS10102'!O133 -> 92.406798 | P42: ='ISS10102'!P133 -> 10.152083 | Q42: =((100-O42)/O42*(365/273))*100 -> 10.986295
A43: =A42+1 -> 490 | B43: =B42+7 -> 37223 | D43: ='ISS10102'!D138 -> 5000000000 | E43: ='ISS10102'!E138 -> 13460500000 | F43: ='ISS10102'!F138 -> 8460500000 | G43: ='ISS10102'!G138 -> 4999900000 | H43: ='ISS10102'!H138 -> 4622696692 | I43: =G43-H43 -> 377203308 | J43: =B43+K43+1 -> 37497 | K43: ='ISS10102'!K138 -> 273 | N43: ='ISS10102'!N138 -> 9.999 | O43: ='ISS10102'!O138 -> 92.455783 | P43: ='ISS10102'!P138 -> 10.086591 | Q43: =((100-O43)/O43*(365/273))*100 -> 10.909637
B45: Total Nov 2001 | D45: =SUM(D40:D43) -> 19000000000 | E45: =SUM(E40:E43) -> 47781400000 | F45: =SUM(F40:F43) -> 28781400000 | G45: =SUM(G40:G43) -> 18999900000 | H45: =SUM(H40:H43) -> 17564029954 | I45: =SUM(I40:I43) -> 1435870046 | O45: =AVERAGEA(O40:O43) -> 92.43819 | P45: =AVERAGEA(P40:P43) -> 10.110112 | Q45: =AVERAGEA(Q40:Q43) -> 10.937239
A47: =A43+1 -> 491 | B47: =B43+7 -> 37230 | D47: ='ISS10102'!D148 -> 5000000000 | E47: ='ISS10102'!E148 -> 11046600000 | F47: ='ISS10102'!F148 -> 6046600000 | G47: ='ISS10102'!G148 -> 5000000000 | H47: ='ISS10102'!H148 -> 4641359698 | I47: =G47-H47 -> 358640302 | J47: =B47+K47+1 -> 37504 | K47: 273 | N47: ='ISS10102'!N148 -> 9.001 | O47: ='ISS10102'!O148 -> 92.827194 | P47: ='ISS10102'!P148 -> 9.5900154 | Q47: =((100-O47)/O47*(365/273))*100 -> 10.331041
A48: =A47+1 -> 492 | B48: =B47+7 -> 37237 | D48: ='ISS10102'!D153 -> 5000000000 | E48: ='ISS10102'!E153 -> 12881000000 | F48: ='ISS10102'!F153 -> 7881000000 | G48: ='ISS10102'!G153 -> 5000000000 | H48: ='ISS10102'!H153 -> 4661725350 | I48: =G48-H48 -> 338274650 | J48: =B48+K48+1 -> 37511 | K48: 273 | N48: ='ISS10102'!N153 -> 8.491 | O48: ='ISS10102'!O153 -> 93.234507 | P48: ='ISS10102'!P153 -> 9.0454394 | Q48: =((100-O48)/O48*(365/273))*100 -> 9.701815
A49: =A48+1 -> 493 | B49: =B48+7 -> 37244 | D49: ='ISS10102'!D158 -> 5000000000 | E49: ='ISS10102'!E158 -> 10769300000 | F49: ='ISS10102'!F158 -> 5769300000 | G49: ='ISS10102'!G158 -> 5000000000 | H49: ='ISS10102'!H158 -> 4649306756 | I49: =G49-H49 -> 350693244 | J49: =B49+K49+1 -> 37518 | K49: 273 | N49: ='ISS10102'!N158 -> 9.304 | O49: ='ISS10102'!O158 -> 92.986135 | P49: ='ISS10102'!P158 -> 9.3775117 | Q49: =((100-O49)/O49*(365/273))*100 -> 10.084849
A50: =A49+1 -> 494 | B50: =B49+7 -> 37251 | D50: ='ISS10102'!D163 -> 4000000000 | E50: ='ISS10102'!E163 -> 3650000000 | F50: ='ISS10102'!F163 -> -350000000 | G50: ='ISS10102'!G163 -> 3650000000 | H50: ='ISS10102'!H163 -> 3386184000 | I50: =G50-H50 -> 263816000 | J50: =B50+K50+1 -> 37525 | K50: 273 | N50: ='ISS10102'!N163 -> 9.261 | O50: ='ISS10102'!O163 -> 92.772164 | P50: ='ISS10102'!P163 -> 9.6635897 | Q50: =((100-O50)/O50*(365/273))*100 -> 10.416475
A52: =A50+1 -> 495 | B52: =B50+7 -> 37258 | D52: 3000000000 | E52: 1051000000 | F52: =E52-D52 -> -1949000000 | G52: 3000000000 | H52: 2786309700 | I52: =G52-H52 -> 213690300 | J52: =B52+K52+1 -> 37532 | K52: 273 | N52: 9.359 | O52: =H52/G52*100 -> 92.87699 | P52: =(100-O52)/100*(365/273)*100 -> 9.5234383 | Q52: =((100-O52)/O52*(365/273))*100 -> 10.253819
...

Sheet maturities - 364
A2: Ref:ISS9899. WK3
A3: worksheet b
A4: - | B4: - | C4: - | D4: - | E4: - | F4: - | G4: - | H4: - | I4: - | J4: - | K4: - | L4: - | M4: - | N4: - | O4: -
A5: Auction | B5: Issue date | C5: Amount offered | D5: Total bids | E5: Over/(Under) | F5: Face Value of | G5: Cost Value | H5: Interest due | I5: Date due | J5: Duration | K5: Implicit annual | L5: Clearing | M5: Lowest | N5: Weighted | O5: Average | P5: Money market yielr
A6: No | C6: in | D6: (Competitive & | E6: Subscribed | F6: issues | K6: interest rate | L6: factor | M6: factor | N6: Average | O6: Discount | Q6: Annualised | R6: Rejected Amount | S6: Bid-to-cover
C7: Auction | D7: Uncompetitive) | L7: (%) | M7: (%) | N7: Price | O7: factor | Q7: yield
B8: (1) | C8: (1a) | D8: (1b) | F8: (2) | G8: (3) | H8: (4) | I8: (5) | J8: (6) | K8: (9) | L8: (10) | M8: (11) | N8: (12) | O8: (13)
A9: - | B9: - | C9: - | D9: - | E9: - | F9: - | G9: - | H9: - | I9: - | J9: - | K9: - | L9: - | M9: - | N9: - | O9: - | Q9: -
A11: 469 | B11: 37076 | C11: ='ISS10102'!D14 -> 5000000000 | D11: ='ISS10102'!E14 -> 6412000000 | E11: ='ISS10102'!F14 -> 1412000000 | F11: ='ISS10102'!G14 -> 5000000000 | G11: ='ISS10102'!H14 -> 4459772680 | H11: ='ISS10102'!I14 -> 540227320 | I11: ='ISS10102'!J14 -> 37441 | J11: ='ISS10102'!K14 -> 364 | M11: ='ISS10102'!N14 -> 10.123 | N11: ='ISS10102'!O14 -> 89.195454 | O11: ='ISS10102'!P14 -> 10.834229 | Q11: =((100-N11)/N11*(365/364))*100 -> 12.146616 | R11: =+IF(F11<C11,IF(F11=D11,0,D11-F11),0) -> 0
A12: =A11+1 -> 470 | B12: =B11+7 -> 37083 | C12: ='ISS10102'!D19 -> 7000000000 | D12: ='ISS10102'!E19 -> 7000000000 | E12: ='ISS10102'!F19 -> 0 | F12: ='ISS10102'!G19 -> 7000000000 | G12: ='ISS10102'!H19 -> 6220102016 | H12: ='ISS10102'!I19 -> 779897984 | I12: ='ISS10102'!J19 -> 37448 | J12: ='ISS10102'!K19 -> 364 | M12: ='ISS10102'!N19 -> 9.916 | N12: ='ISS10102'!O19 -> 88.8586 | O12: ='ISS10102'!P19 -> 11.172008 | Q12: =((100-N12)/N12*(365/364))*100 -> 12.572793 | R12: =+IF(F12<C12,IF(F12=D12,0,D12-F12),0) -> 0
A13: =A12+1 -> 471 | B13: =B12+7 -> 37090 | C13: ='ISS10102'!D24 -> 7000000000 | D13: ='ISS10102'!E24 -> 7000000000 | E13: ='ISS10102'!F24 -> 0 | F13: ='ISS10102'!G24 -> 7000000000 | G13: ='ISS10102'!H24 -> 6001002268 | H13: ='ISS10102'!I24 -> 998997732 | I13: ='ISS10102'!J24 -> 37455 | J13: ='ISS10102'!K24 -> 364 | M13: ='ISS10102'!N24 -> 11 | N13: ='ISS10102'!O24 -> 85.728604 | O13: ='ISS10102'!P24 -> 14.310603 | Q13: =((100-N13)/N13*(365/364))*100 -> 16.692915 | R13: =+IF(F13<C13,IF(F13=D13,0,D13-F13),0) -> 0
